
<mujoco>
    <compiler angle="radian"/>
    <option timestep="0.005" gravity="0 0 -9.81"/>
    
    <worldbody>
        <light pos="0 0 3" dir="0 0 -1" directional="true" castshadow="true"/>
        <geom type="plane" size="2 2 0.1" rgba="0.9 0.9 0.9 1"/>
        
        <body name="target_cabinet" pos="0.6 0 0.1">
            <geom size="0.03413 0.682575 0.017065" pos="-0.51681 -0.37247 0.09596" quat="0.5 0.5 -0.5 -0.5" type="box" />
    <geom size="0.03413 0.682575 0.017065" pos="-0.51681 0.37836 0.09596" quat="0.5 0.5 -0.5 -0.5" type="box" />
    <geom size="0.381105 0.068255 0.017065" pos="0.54119 0.00294 0.71028" quat="0.5 0.5 -0.5 -0.5" type="box" />
    <geom size="0.34129 0.03413 0.017065" pos="-0.51681 0.00294 -0.55249" quat="0.5 0.5 -0.5 -0.5" type="box" />
    <geom size="0.34129 0.03413 0.017065" pos="-0.51681 0.00294 -0.04625" quat="0.5 0.5 -0.5 -0.5" type="box" />
    <geom size="0.34129 0.03413 0.017065" pos="-0.51681 0.00294 0.44862" quat="0.5 0.5 -0.5 -0.5" type="box" />
    <geom size="0.34129 0.03413 0.017065" pos="-0.51681 0.00294 0.74441" quat="0.5 0.5 -0.5 -0.5" type="box" />
    <geom size="0.06826 0.011375 0.06826" pos="-0.43148 -0.3099 0.73303" quat="0.5 0.5 -0.5 -0.5" type="box" />
    <geom size="0.068255 0.011375 0.06826" pos="-0.43148 0.31579 0.73303" quat="0.5 0.5 -0.5 -0.5" type="box" />
    <geom size="0.06826 0.011375 0.068255" pos="0.45587 -0.3099 0.73303" quat="0.5 0.5 -0.5 -0.5" type="box" />
    <geom size="0.068255 0.011375 0.068255" pos="0.45587 0.31579 0.73303" quat="0.5 0.5 -0.5 -0.5" type="box" />
    <geom size="0.00853 0.682575 0.47496" pos="0.08329 0.39258 0.09596" quat="0.5 0.5 -0.5 -0.5" type="box" />
    <geom size="0.00853 0.682575 0.054035" pos="-0.4457 0.39258 0.09596" quat="0.5 0.5 -0.5 -0.5" type="box" />
    <geom size="0.00853 0.682575 0.054035" pos="-0.4457 -0.38669 0.09596" quat="0.5 0.5 -0.5 -0.5" type="box" />
    <geom size="0.00853 0.682575 0.47496" pos="0.08329 -0.38669 0.09596" quat="0.5 0.5 -0.5 -0.5" type="box" />
    <geom size="0.381105 0.63707 0.00569" pos="0.51844 0.00294 0.08458" quat="0.5 0.5 -0.5 -0.5" type="box" />
    <geom size="0.381105 0.011375 0.506245" pos="0.0065 0.00294 -0.54111" quat="0.5 0.5 -0.5 -0.5" type="box" />
    <geom size="0.136515 0.09215 0.0005" pos="0.52412 0.24185 -0.4319" quat="0.5 0.5 -0.5 -0.5" type="box" />
    <geom size="0.0005 0.02275 0.03371" pos="-0.4319 0.31295 -0.19129" quat="0.5 0.5 -0.5 -0.5" type="box" />
    <geom size="0.0005 0.022755 0.03371" pos="-0.4319 0.31295 0.31495" quat="0.5 0.5 -0.5 -0.5" type="box" />
    <geom size="0.0005 0.022755 0.03371" pos="-0.4319 0.31295 0.61642" quat="0.5 0.5 -0.5 -0.5" type="box" />
    <geom size="0.00853 0.102385 0.47496" pos="0.08329 -0.38669 -0.68901" quat="0.5 0.5 -0.5 -0.5" type="box" />
    <geom size="0.381105 0.13367 0.017065" pos="0.54119 0.00294 -0.65772" quat="0.5 0.5 -0.5 -0.5" type="box" />
    <geom size="0.00853 0.102385 0.47496" pos="0.08329 0.39258 -0.68901" quat="0.5 0.5 -0.5 -0.5" type="box" />
    <geom size="0.381105 0.11945 0.00853" pos="-0.38313 0.00294 -0.67194" quat="0.5 0.5 -0.5 -0.5" type="box" />
    <body name="link_0" quat="0.5 0.5 -0.5 -0.5">
      <inertial pos="0 0 0" mass="1" diaginertia="0.01 0.01 0.01" />
      <joint name="joint_0" pos="0 0 0" axis="0 0 1" type="slide" range="0 0.8" />
      <geom size="0.39248 0.254545 0.017065" pos="-0.00294 -0.31501 0.55093" type="box" />
      <geom size="0.28725 0.18202 0.011375" pos="-0.00294 -0.31643 0.52249" type="box" />
      <geom size="0.011375 0.18202 0.45505" pos="0.29568 -0.31643 0.07882" type="box" />
      <geom size="0.011375 0.18202 0.45505" pos="-0.30157 -0.31643 0.07882" type="box" />
      <geom size="0.28725 0.18202 0.011375" pos="-0.00294 -0.31643 -0.36486" type="box" />
      <geom size="0.28725 0.0005 0.4323" pos="-0.00294 -0.46717 0.07882" type="box" />
      <geom size="0.28725 0.0005 0.4323" pos="-0.00294 -0.4757 0.07882" type="box" />
      <geom size="0.10708 0.010525 0.022935" pos="-0.00294 -0.31501 0.59093" type="box" />
    </body>
    <body name="link_1" quat="0.5 0.5 -0.5 -0.5">
      <inertial pos="0 0 0" mass="1" diaginertia="0.01 0.01 0.01" />
      <joint name="joint_1" pos="0 0 0" axis="0 0 1" type="slide" range="0 0.8" />
      <geom size="0.39248 0.241745 0.017065" pos="-0.00294 0.19834 0.55093" type="box" />
      <geom size="0.28725 0.18202 0.011375" pos="-0.00294 0.18981 0.52249" type="box" />
      <geom size="0.011375 0.18202 0.45505" pos="0.29568 0.18981 0.07882" type="box" />
      <geom size="0.011375 0.18202 0.45505" pos="-0.30157 0.18981 0.07882" type="box" />
      <geom size="0.28725 0.18202 0.011375" pos="-0.00294 0.18981 -0.36486" type="box" />
      <geom size="0.28725 0.0005 0.4323" pos="-0.00294 0.03054 0.07882" type="box" />
      <geom size="0.28725 0.0005 0.4323" pos="-0.00294 0.03908 0.07882" type="box" />
      <geom size="0.10708 0.010525 0.022935" pos="-0.00294 0.19834 0.59093" type="box" />
    </body>
    <body name="link_2" quat="0.5 0.5 -0.5 -0.5">
      <inertial pos="0 0 0" mass="1" diaginertia="0.01 0.01 0.01" />
      <joint name="joint_2" pos="0 0 0" axis="0 0 1" type="slide" range="0 0.8" />
      <geom size="0.28725 0.06826 0.011375" pos="-0.00294 0.60505 0.52249" type="box" />
      <geom size="0.39248 0.15216 0.017065" pos="-0.00294 0.60931 0.55093" type="box" />
      <geom size="0.011375 0.06826 0.45505" pos="0.29568 0.60505 0.07882" type="box" />
      <geom size="0.011375 0.06826 0.45505" pos="-0.30157 0.60505 0.07882" type="box" />
      <geom size="0.28725 0.06826 0.011375" pos="-0.00294 0.60505 -0.36486" type="box" />
      <geom size="0.28725 0.0005 0.4323" pos="-0.00294 0.56807 0.07882" type="box" />
      <geom size="0.28725 0.0005 0.4323" pos="-0.00294 0.55954 0.07882" type="box" />
      <geom size="0.10708 0.010525 0.022935" pos="-0.00294 0.60931 0.59093" type="box" />
    </body>
  
        </body>
        
        <body name="left_arm" pos="0 0.4 0">
            <geom type="cylinder" size="0.05 0.2" rgba="0.8 0.2 0.2 1"/>
            <joint name="left_j1" type="hinge" axis="0 0 1"/>
            <body pos="0.3 0 0.2">
                <geom type="cylinder" size="0.04 0.2" rgba="0.8 0.2 0.2 1"/>
                <joint name="left_j2" type="hinge" axis="0 1 0"/>
            </body>
        </body>
        
        <body name="right_arm" pos="0 -0.4 0">
            <geom type="cylinder" size="0.05 0.2" rgba="0.2 0.2 0.8 1"/>
            <joint name="right_j1" type="hinge" axis="0 0 1"/>
            <body name="right_wrist" pos="0.3 0 0.2">
                <geom type="cylinder" size="0.04 0.2" rgba="0.2 0.2 0.8 1"/>
                <joint name="right_j2" type="hinge" axis="0 1 0"/>
                <camera name="hand_camera" pos="0.1 0 0" fovy="60" zaxis="1 0 0"/>
            </body>
        </body>
    </worldbody>
</mujoco>
